Workbook

Sheet Sheet1
A1: THIS IS FOR THE END USER
A3: SET UP YOUR DESIGN GEOMETRY HERE

Sheet FORMAT
D8: KEY
D9: Label
B10: TITLE | D10: Constant
D11: Computed
C14: 0

Sheet General
D5: General design choices | E5: Aerodynamic | F5: Propulsion | G5: Weight
C6: Type | D6: "Jet fighter"
C7: Wing config | D7: Delta
C8: Engine count | D8: 1
C9: Pilot | D9: 1
C10: Sub/supersonic | D10: Supersonic
C11: Tail config | D11: Fighter
C12: engine type | D12: "low bpr turbofan"
C13: isafterburning | D13: Y
C14: fuel_type | D14: JP-4

Sheet Wings
C13: Main | D13: Horizontal Tail | E13: Vertical Tail | F13: Strakes
B14: Span (ft) | C14: 30 | D14: 18 | E14: 9.8 | F14: 5.48
B15: Sweep (LE, deg) | C15: 40 | D15: 40 | E15: 40 | F15: 74
B16: Root chord length (ft) | C16: 16.29 | D16: 9.78 | E16: 8.16 | F16: 7.3
B17: Tip chord length (ft) | C17: 3.71 | D17: 2.22 | E17: 4.08 | F17: 0
B18: Taper ratio | C18: =C17/C16 -> 0.22774708 | D18: =D17/D16 -> 0.22699387 | E18: =E17/E16 -> 0.5 | F18: =F17/F16 -> 0
B19: Dihedral (deg) | C19: =0 -> 0 | D19: =0 -> 0 | E19: =0 -> 0 | F19: =0 -> 0
B20: Average chord | C20: =(C16+C17)/2 -> 10 | D20: =(D16+D17)/2 -> 6 | E20: =(E16+E17)/2 -> 6.12 | F20: =(F16+F17)/2 -> 3.65
B21: Mean geometric chord | C21: =(2/3) * (C16) * ( (1 + C18 + C18^2) / (1 + C18)) -> 11.318803 | D21: =(2/3) * (D16) * ( (1 + D18 + D18^2) / (1 + D18)) -> 6.7938 | E21: =(2/3) * (E16) * ( (1 + E18 + E18^2) / (1 + E18)) -> 6.3466667 | F21: =(2/3) * (F16) * ( (1 + F18 + F18^2) / (1 + F18)) -> 4.8666667
B22: Angle of quarter-chord line (rad) | C22: =TAN(C15*PI()/180) + C16/(2*C14)*(C18-1) -> 0.62943296 | D22: =TAN(D15*PI()/180) + D16/(2*D14)*(D18-1) -> 0.62909963 | E22: =TAN(E15*PI()/180) + E16/(2*E14)*(E18-1) -> 0.63093637 | F22: =TAN(F15*PI()/180) + F16/(2*F14)*(F18-1) -> 2.821356
B23: Planform area (ft^2) | C23: =(C14*C16*(1+C18)/2) -> 300 | D23: =(D14*D16*(1+D18)/2) -> 108 | E23: =(E14*E16*(1+E18)/2) -> 59.976 | F23: =(F14*F16*(1+F18)/2) -> 20.002
B24: Aspect ratio | C24: =C14^2/C23 -> 3 | D24: =D14^2/D23 -> 3 | E24: =E14^2/E23 -> 1.6013072 | F24: =F14^2/F23 -> 1.5013699
B25: Airfoil | C25: NACA 1404 | D25: NACA 0004 | E25: NACA 0004 | F25: NACA 0004
B26: t/c | C26: 0.04 | D26: 0.04 | E26: 0.04 | F26: 0.04
B27: cl max | C27: 1.43 | D27: 0 | E27: 0 | F27: 0
B28: alpha L=0 | C28: =-1.0469 -> -1.0469 | D28: 0 | E28: 0 | F28: 0
B29: cl alpha | C29: 0.1 | D29: 0.105 | E29: 0.105 | F29: 0.105
B30: c_VT | E30: 0.07
B31: c_HT | D31: 0.4
B32: Taper ratio, qc | C32: =0.3 -> 0.3
B33: Mean geometric chord location (ymac/b) | C33: =(1/6)*((1+2*C18)/(1+C18)) -> 0.19758333 | D33: =(1/6)*((1+2*D18)/(1+D18)) -> 0.1975 | E33: =(1/6)*((1+2*E18)/(1+E18)) -> 0.22222222 | F33: =(1/6)*((1+2*F18)/(1+F18)) -> 0.16666667
B34: ymac | C34: =C33*C14 -> 5.9275 | D34: =D33*D14 -> 3.555 | E34: =E33*E14 -> 2.1777778 | F34: =F33*F14 -> 0.91333333
B35: x/c | C35: 0.5 | D35: 0.04 | E35: 0.04
B36: Q | C36: 1 | D36: 1.05 | E36: 1.05 | F36: 1
B37: Airfoil type | C37: cambered | D37: uncambered | E37: uncambered | F37: uncambered
B38: Exposed root chord | C38: 13.36 | D38: 6.84 | E38: 7.12 | F38: 7.3
B39: Exposed half-span | C39: 11.5 | D39: 5.5 | E39: 7.3 | F39: 2.74
B40: x location | C40: 17.79 | D40: 36 | E40: 36 | F40: 12
B41: Kfus | C41: 0.06

Sheet Fuselage
C13: Total | D13: Fuselage | E13: Nose
B14: Length (ft) | C14: 46.5 | D14: =C14*(2/3) -> 31 | E14: =C14/3 -> 15.5
B15: Max width (ft) | C15: 7.5 | D15: 7.5 | E15: 7
B16: Max height (ft) | C16: 5 | D16: 5
B17: Fw (ft)
B18: Shape
B19: Area (top) (ft^2) | D19: =D14*D15 -> 232.5 | E19: =(1/2)*E15*E14 -> 54.25
B20: Area (side) (ft^2) | D20: =D19 -> 232.5 | E20: =E19 -> 54.25
B21: Q | D21: 1 | E21: 1

Sheet Propulsion
C13: Dry | D13: Wet | E13: Bypass Ratio | F13: Inlet Area
B14: Thrust (sea level) (lbf) | C14: 15000 | D14: 23770
B15: TSFC (sea level) (per hour) | C15: 0.7 | D15: 2.2
B16: E | C16: 1 | D16: 0.5
B17: F1 | C17: 0.3 | D17: 0.1
B18: F2 | C18: 1.7 | D18: 2.2
B19: Bypass Ratio | E19: 0.63
B20: Inlet area | F20: =PI()*(3.54/2)^2 -> 9.8422956

Sheet Weights
C3: Weights | D3: Coefficients | E3: Izz
B4: Fixed (lbf) | C4: 5100
B5: Payload, drop (lbf) | C5: 4400
B6: Payload, fixed (lbf) | C6: 700
B7: WTO_guess | C7: 45000
B8: AR | D8: 3
B9: Art | D9: 3
B10: Arv | D10: 1.6
B11: Bh | D11: =Wings!D14 -> 18
B12: Bw | D12: =Wings!C14 -> 30
B13: D | D13: 7.5
B14: De | D14: 3.45
B15: Fw | D15: 7
B16: Ht | D16: =Wings!D31 -> 0.4
B17: Ht/Hv | D17: 0
B18: Hv | D18: 3.5
B19: Iyaw | D19: =E107 -> 100.61584
B20: Kcb | D20: 1
B21: Kd | D21: 3.43
B22: Kdoor | D22: 1
B23: Kdw | D23: 0.768
B24: Kdwf | D24: 0.774
B25: Kh | D25: 0.12
B26: KLg | D26: 1.12
B27: Kmc | D27: 1
B28: Kmp | D28: 1
B29: Kng | D29: 1
B30: Knp | D30: 1
B31: KP | D31: 1
... B40: Kvsh | D40: 1
B41: Kws | D41: =0.75*((1+2*Wings!C18)/(1+Wings!C18))*(Wings!C14/D48)*(TAN(Wings!C15*PI()/180)) -> 0.72199786
B42: Ky | D42: =0.3*D53 -> 0.71175
B43: Kz | D43: =D53 -> 2.3725
B44: L | D44: =Fuselage!D14 -> 31
B45: La | D45: =15*5280 -> 79200
B46: Ld | D46: 15.92
B47: Lec | D47: 0
B48: Lf | D48: =Fuselage!D14 -> 31
B49: Lm | D49: =5.3*12 -> 63.6
B50: Ln | D50: =5.3*12 -> 63.6
...

Sheet Stability&Control
E7: Weight (lbf) | F7: CG X-Location (fT) | G7: X-MAC | H7: Y-MAC
D8: Wing | E8: 0 | F8: 27.28
D9: Fuselage | E9: 3652 | F9: 26
D10: HT | E10: 648 | F10: 41
D11: VT | E11: 360 | F11: 40
D12: Nacelles | E12: 186 | F12: 29
D13: Strakes | E13: 90 | F13: 17
D14: Engine | E14: 4730 | F14: 33
D15: Gear | E15: 1066 | F15: 26
D16: Inlet duct | E16: 728 | F16: 22
D17: Controls | E17: 472 | F17: 27
D18: Electrical | E18: 533 | F18: 33
D19: Hydraulics | E19: 367 | F19: 33
... D29: Fuel 3 | E29: 2098 | F29: 28

Sheet Protuberances
E10: Y/N | F10: USAF/USN | G10: D/q (ft^2) | H10: D/q (m^2)
D11: Arresting hook | E11: Y | F11: USAF | G11: 0.1 | H11: 0.009
D12: Machine gun ports | E12: N
D13: Cannon port | E13: Y | G13: 0.2 | H13: 0.019
D14: Exposed pilot - prone | E14: N
D15: Exposed pilot - seated | E15: N
D16: Exposed pilot - spread eagle | E16: N

Sheet Skin roughness
D6: k (ft) | E6: k (m)
C7: Camo paint on aluminum | D7: =3.33*10^(-5) -> 3.33e-05 | E7: =1.015*10^(-5) -> 1.015e-05
C8: Smooth paint | D8: =2.08*10^(-5) -> 2.08e-05 | E8: =0.634*10^(-5) -> 6.34e-06
C9: Production sheet metal | D9: =1.33*10^(-5) -> 1.33e-05 | E9: =0.405*10^(-5) -> 4.05e-06
C10: Polished sheet metal | D10: =0.5*10^(-5) -> 5e-06 | E10: =0.152*10^(-5) -> 1.52e-06
C11: Smooth molded composite | D11: =0.7*10^(-5) -> 7e-06 | E11: =0.052*10^(-5) -> 5.2e-07
